<?xml version="1.0"?>
<robot name="ur3" xmlns:xacro="http://www.ros.org/wiki/xacro">

  <!-- BASE LINK -->
  <link name="base_link">
    <visual>
      <geometry>
        <mesh filename="package://ur_description/meshes/ur3/visual/base.dae"/>
      </geometry>
    </visual>
    <collision>
      <geometry>
        <mesh filename="package://ur_description/meshes/ur3/collision/base.stl"/>
      </geometry>
    </collision>
  </link>

  <!-- JOINT 1: shoulder_pan -->
  <joint name="shoulder_pan_joint" type="revolute">
    <parent link="base_link"/>
    <child link="shoulder_link"/>
    <origin xyz="0 0 0.1519" rpy="0 0 0"/>
    <axis xyz="0 0 1"/>
    <limit lower="-3.1415926535" upper="3.1415926535" effort="330" velocity="2.16"/>
  </joint>

  <link name="shoulder_link">
    <visual>
      <geometry>
        <mesh filename="package://ur_description/meshes/ur3/visual/shoulder.dae"/>
      </geometry>
    </visual>
    <collision>
      <geometry>
        <mesh filename="package://ur_description/meshes/ur3/collision/shoulder.stl"/>
      </geometry>
    </collision>
  </link>

  <!-- JOINT 2: shoulder_lift -->
  <joint name="shoulder_lift_joint" type="revolute">
    <parent link="shoulder_link"/>
    <child link="upper_arm_link"/>
    <origin xyz="0 0.1198 0" rpy="0 0 0"/>
    <axis xyz="0 1 0"/>
    <limit lower="-3.1415926535" upper="3.1415926535" effort="330" velocity="2.16"/>
  </joint>

  <link name="upper_arm_link">
    <visual>
      <geometry>
        <mesh filename="package://ur_description/meshes/ur3/visual/upperarm.dae"/>
      </geometry>
    </visual>
    <collision>
      <geometry>
        <mesh filename="package://ur_description/meshes/ur3/collision/upperarm.stl"/>
      </geometry>
    </collision>
  </link>

  <!-- JOINT 3: elbow -->
  <joint name="elbow_joint" type="revolute">
    <parent link="upper_arm_link"/>
    <child link="forearm_link"/>
    <origin xyz="0 -0.0925 0.24365" rpy="0 0 0"/>
    <axis xyz="0 1 0"/>
    <limit lower="-3.1415926535" upper="3.1415926535" effort="150" velocity="3.15"/>
  </joint>

  <link name="forearm_link">
    <visual>
      <geometry>
        <mesh filename="package://ur_description/meshes/ur3/visual/forearm.dae"/>
      </geometry>
    </visual>
    <collision>
      <geometry>
        <mesh filename="package://ur_description/meshes/ur3/collision/forearm.stl"/>
      </geometry>
    </collision>
  </link>

  <!-- JOINT 4: wrist_1 -->
  <joint name="wrist_1_joint" type="revolute">
    <parent link="forearm_link"/>
    <child link="wrist_1_link"/>
    <origin xyz="0 0 0.21325" rpy="0 0 0"/>
    <axis xyz="0 1 0"/>
    <limit lower="-3.1415926535" upper="3.1415926535" effort="54" velocity="3.2"/>
  </joint>

  <link name="wrist_1_link">
    <visual>
      <geometry>
        <mesh filename="package://ur_description/meshes/ur3/visual/wrist1.dae"/>
      </geometry>
    </visual>
    <collision>
      <geometry>
        <mesh filename="package://ur_description/meshes/ur3/collision/wrist1.stl"/>
      </geometry>
    </collision>
  </link>

  <!-- JOINT 5: wrist_2 -->
  <joint name="wrist_2_joint" type="revolute">
    <parent link="wrist_1_link"/>
    <child link="wrist_2_link"/>
    <origin xyz="0 0.08505 0" rpy="0 0 0"/>
    <axis xyz="0 0 1"/>
    <limit lower="-3.1415926535" upper="3.1415926535" effort="54" velocity="3.2"/>
  </joint>

  <link name="wrist_2_link">
    <visual>
      <geometry>
        <mesh filename="package://ur_description/meshes/ur3/visual/wrist2.dae"/>
      </geometry>
    </visual>
    <collision>
      <geometry>
        <mesh filename="package://ur_description/meshes/ur3/collision/wrist2.stl"/>
      </geometry>
    </collision>
  </link>

  <!-- JOINT 6: wrist_3 -->
  <joint name="wrist_3_joint" type="revolute">
    <parent link="wrist_2_link"/>
    <child link="wrist_3_link"/>
    <origin xyz="0 0 0.08535" rpy="0 0 0"/>
    <axis xyz="0 1 0"/>
    <limit lower="-3.1415926535" upper="3.1415926535" effort="54" velocity="3.2"/>
  </joint>

  <link name="wrist_3_link">
    <visual>
      <geometry>
        <mesh filename="package://ur_description/meshes/ur3/visual/wrist3.dae"/>
      </geometry>
    </visual>
    <collision>
      <geometry>
        <mesh filename="package://ur_description/meshes/ur3/collision/wrist3.stl"/>
      </geometry>
    </collision>
  </link>

  <!-- TOOL0 FRAME -->
  <joint name="wrist_3_link-tool0_fixed_joint" type="fixed">
    <origin xyz="0 0 0.0" rpy="0 0 0"/>
    <parent link="wrist_3_link"/>
    <child link="tool0"/>
  </joint>

  <link name="tool0"/>
</robot>
